Workbook
Name country: Dashboard!#REF!
Name hybrid: calculator!$O$4
Name job: Dashboard!$F$5
Name job_count: calculator!$A$8
Name median_salary: calculator!$D$19
Name on_site: calculator!$O$2
Name remote: calculator!$O$3
Name year: Dashboard!$J$5

Sheet data
A1: work_year | B1: experience_level | C1: employment_type | D1: job_title | E1: salary | F1: salary_currency | G1: salary_in_usd | H1: employee_residence | I1: remote_ratio | J1: company_location | K1: company_size | L1: job_title_short | M1: job_sch | N1: job_exp | O1: job_location | P1: job_company_size | Q1: job_type
A2: 2023 | B2: MI | C2: FT | D2: Data Analyst | E2: 165000 | F2: USD | G2: 165000 | H2: AU | I2: 0 | J2: AU | K2: M | L2: =_xlfn.XLOOKUP($D2,mapping!$B$2:$B$124,mapping!$A$2:$A$124,,0) -> Data Analyst | M2: =_xlfn.XLOOKUP($C2,mapping!$J$2:$J$5,mapping!$K$2:$K$5,,0) -> Full-Time | N2: =_xlfn.XLOOKUP($B2,mapping!$G$2:$G$5,mapping!$H$2:$H$5,,0) -> Mid-Level | O2: =_xlfn.XLOOKUP($J2,mapping!$D$2:$D$56,mapping!$E$2:$E$56,,0) -> Australia | P2: =_xlfn.XLOOKUP($K2,mapping!$P$2:$P$4,mapping!$Q$2:$Q$4,,0) -> Medium | Q2: =_xlfn.XLOOKUP($I2,mapping!$M$2:$M$4,mapping!$N$2:$N$4,,0) -> On-site
A3: 2023 | B3: MI | C3: FT | D3: Data Analyst | E3: 70000 | F3: USD | G3: 70000 | H3: US | I3: 100 | J3: US | K3: M | L3: =_xlfn.XLOOKUP($D3,mapping!$B$2:$B$124,mapping!$A$2:$A$124,,0) -> Data Analyst | M3: =_xlfn.XLOOKUP($C3,mapping!$J$2:$J$5,mapping!$K$2:$K$5,,0) -> Full-Time | N3: =_xlfn.XLOOKUP($B3,mapping!$G$2:$G$5,mapping!$H$2:$H$5,,0) -> Mid-Level | O3: =_xlfn.XLOOKUP($J3,mapping!$D$2:$D$56,mapping!$E$2:$E$56,,0) -> United States | P3: =_xlfn.XLOOKUP($K3,mapping!$P$2:$P$4,mapping!$Q$2:$Q$4,,0) -> Medium | Q3: =_xlfn.XLOOKUP($I3,mapping!$M$2:$M$4,mapping!$N$2:$N$4,,0) -> Remote
A4: 2024 | B4: MI | C4: FT | D4: Machine Learning Engineer | E4: 85000 | F4: EUR | G4: 94444 | H4: IE | I4: 100 | J4: IE | K4: M | L4: =_xlfn.XLOOKUP($D4,mapping!$B$2:$B$124,mapping!$A$2:$A$124,,0) -> Machine Learning Engineer | M4: =_xlfn.XLOOKUP($C4,mapping!$J$2:$J$5,mapping!$K$2:$K$5,,0) -> Full-Time | N4: =_xlfn.XLOOKUP($B4,mapping!$G$2:$G$5,mapping!$H$2:$H$5,,0) -> Mid-Level | O4: =_xlfn.XLOOKUP($J4,mapping!$D$2:$D$56,mapping!$E$2:$E$56,,0) -> Ireland | P4: =_xlfn.XLOOKUP($K4,mapping!$P$2:$P$4,mapping!$Q$2:$Q$4,,0) -> Medium | Q4: =_xlfn.XLOOKUP($I4,mapping!$M$2:$M$4,mapping!$N$2:$N$4,,0) -> Remote
A5: 2024 | B5: SE | C5: FT | D5: Data Scientist | E5: 92700 | F5: USD | G5: 92700 | H5: US | I5: 0 | J5: US | K5: M | L5: =_xlfn.XLOOKUP($D5,mapping!$B$2:$B$124,mapping!$A$2:$A$124,,0) -> Data Scientist | M5: =_xlfn.XLOOKUP($C5,mapping!$J$2:$J$5,mapping!$K$2:$K$5,,0) -> Full-Time | N5: =_xlfn.XLOOKUP($B5,mapping!$G$2:$G$5,mapping!$H$2:$H$5,,0) -> Senior | O5: =_xlfn.XLOOKUP($J5,mapping!$D$2:$D$56,mapping!$E$2:$E$56,,0) -> United States | P5: =_xlfn.XLOOKUP($K5,mapping!$P$2:$P$4,mapping!$Q$2:$Q$4,,0) -> Medium | Q5: =_xlfn.XLOOKUP($I5,mapping!$M$2:$M$4,mapping!$N$2:$N$4,,0) -> On-site
A6: 2023 | B6: MI | C6: FT | D6: Research Engineer | E6: 150000 | F6: USD | G6: 150000 | H6: US | I6: 0 | J6: US | K6: M | L6: =_xlfn.XLOOKUP($D6,mapping!$B$2:$B$124,mapping!$A$2:$A$124,,0) -> Researcher | M6: =_xlfn.XLOOKUP($C6,mapping!$J$2:$J$5,mapping!$K$2:$K$5,,0) -> Full-Time | N6: =_xlfn.XLOOKUP($B6,mapping!$G$2:$G$5,mapping!$H$2:$H$5,,0) -> Mid-Level | O6: =_xlfn.XLOOKUP($J6,mapping!$D$2:$D$56,mapping!$E$2:$E$56,,0) -> United States | P6: =_xlfn.XLOOKUP($K6,mapping!$P$2:$P$4,mapping!$Q$2:$Q$4,,0) -> Medium | Q6: =_xlfn.XLOOKUP($I6,mapping!$M$2:$M$4,mapping!$N$2:$N$4,,0) -> On-site
A7: 2024 | B7: MI | C7: FT | D7: Research Engineer | E7: 26000 | F7: EUR | G7: 28888 | H7: PT | I7: 0 | J7: PT | K7: M | L7: =_xlfn.XLOOKUP($D7,mapping!$B$2:$B$124,mapping!$A$2:$A$124,,0) -> Researcher | M7: =_xlfn.XLOOKUP($C7,mapping!$J$2:$J$5,mapping!$K$2:$K$5,,0) -> Full-Time | N7: =_xlfn.XLOOKUP($B7,mapping!$G$2:$G$5,mapping!$H$2:$H$5,,0) -> Mid-Level | O7: =_xlfn.XLOOKUP($J7,mapping!$D$2:$D$56,mapping!$E$2:$E$56,,0) -> Portugal | P7: =_xlfn.XLOOKUP($K7,mapping!$P$2:$P$4,mapping!$Q$2:$Q$4,,0) -> Medium | Q7: =_xlfn.XLOOKUP($I7,mapping!$M$2:$M$4,mapping!$N$2:$N$4,,0) -> On-site
A8: 2023 | B8: EX | C8: FT | D8: Machine Learning Engineer | E8: 145000 | F8: USD | G8: 145000 | H8: US | I8: 100 | J8: US | K8: M | L8: =_xlfn.XLOOKUP($D8,mapping!$B$2:$B$124,mapping!$A$2:$A$124,,0) -> Machine Learning Engineer | M8: =_xlfn.XLOOKUP($C8,mapping!$J$2:$J$5,mapping!$K$2:$K$5,,0) -> Full-Time | N8: =_xlfn.XLOOKUP($B8,mapping!$G$2:$G$5,mapping!$H$2:$H$5,,0) -> Executive | O8: =_xlfn.XLOOKUP($J8,mapping!$D$2:$D$56,mapping!$E$2:$E$56,,0) -> United States | P8: =_xlfn.XLOOKUP($K8,mapping!$P$2:$P$4,mapping!$Q$2:$Q$4,,0) -> Medium | Q8: =_xlfn.XLOOKUP($I8,mapping!$M$2:$M$4,mapping!$N$2:$N$4,,0) -> Remote
A9: 2022 | B9: SE | C9: FT | D9: Data Scientist | E9: 130000 | F9: USD | G9: 130000 | H9: US | I9: 100 | J9: US | K9: M | L9: =_xlfn.XLOOKUP($D9,mapping!$B$2:$B$124,mapping!$A$2:$A$124,,0) -> Data Scientist | M9: =_xlfn.XLOOKUP($C9,mapping!$J$2:$J$5,mapping!$K$2:$K$5,,0) -> Full-Time | N9: =_xlfn.XLOOKUP($B9,mapping!$G$2:$G$5,mapping!$H$2:$H$5,,0) -> Senior | O9: =_xlfn.XLOOKUP($J9,mapping!$D$2:$D$56,mapping!$E$2:$E$56,,0) -> United States | P9: =_xlfn.XLOOKUP($K9,mapping!$P$2:$P$4,mapping!$Q$2:$Q$4,,0) -> Medium | Q9: =_xlfn.XLOOKUP($I9,mapping!$M$2:$M$4,mapping!$N$2:$N$4,,0) -> Remote
A10: 2023 | B10: SE | C10: FT | D10: Data Scientist | E10: 159832 | F10: USD | G10: 159832 | H10: US | I10: 0 | J10: US | K10: M | L10: =_xlfn.XLOOKUP($D10,mapping!$B$2:$B$124,mapping!$A$2:$A$124,,0) -> Data Scientist | M10: =_xlfn.XLOOKUP($C10,mapping!$J$2:$J$5,mapping!$K$2:$K$5,,0) -> Full-Time | N10: =_xlfn.XLOOKUP($B10,mapping!$G$2:$G$5,mapping!$H$2:$H$5,,0) -> Senior | O10: =_xlfn.XLOOKUP($J10,mapping!$D$2:$D$56,mapping!$E$2:$E$56,,0) -> United States | P10: =_xlfn.XLOOKUP($K10,mapping!$P$2:$P$4,mapping!$Q$2:$Q$4,,0) -> Medium | Q10: =_xlfn.XLOOKUP($I10,mapping!$M$2:$M$4,mapping!$N$2:$N$4,,0) -> On-site
A11: 2024 | B11: SE | C11: FT | D11: Data Engineer | E11: 160000 | F11: USD | G11: 160000 | H11: US | I11: 0 | J11: US | K11: M | L11: =_xlfn.XLOOKUP($D11,mapping!$B$2:$B$124,mapping!$A$2:$A$124,,0) -> Data Engineer | M11: =_xlfn.XLOOKUP($C11,mapping!$J$2:$J$5,mapping!$K$2:$K$5,,0) -> Full-Time | N11: =_xlfn.XLOOKUP($B11,mapping!$G$2:$G$5,mapping!$H$2:$H$5,,0) -> Senior | O11: =_xlfn.XLOOKUP($J11,mapping!$D$2:$D$56,mapping!$E$2:$E$56,,0) -> United States | P11: =_xlfn.XLOOKUP($K11,mapping!$P$2:$P$4,mapping!$Q$2:$Q$4,,0) -> Medium | Q11: =_xlfn.XLOOKUP($I11,mapping!$M$2:$M$4,mapping!$N$2:$N$4,,0) -> On-site
A12: 2023 | B12: SE | C12: FT | D12: Machine Learning Engineer | E12: 198200 | F12: USD | G12: 198200 | H12: US | I12: 100 | J12: US | K12: M | L12: =_xlfn.XLOOKUP($D12,mapping!$B$2:$B$124,mapping!$A$2:$A$124,,0) -> Machine Learning Engineer | M12: =_xlfn.XLOOKUP($C12,mapping!$J$2:$J$5,mapping!$K$2:$K$5,,0) -> Full-Time | N12: =_xlfn.XLOOKUP($B12,mapping!$G$2:$G$5,mapping!$H$2:$H$5,,0) -> Senior | O12: =_xlfn.XLOOKUP($J12,mapping!$D$2:$D$56,mapping!$E$2:$E$56,,0) -> United States | P12: =_xlfn.XLOOKUP($K12,mapping!$P$2:$P$4,mapping!$Q$2:$Q$4,,0) -> Medium | Q12: =_xlfn.XLOOKUP($I12,mapping!$M$2:$M$4,mapping!$N$2:$N$4,,0) -> Remote
A13: 2023 | B13: SE | C13: FT | D13: Data Analyst | E13: 85000 | F13: USD | G13: 85000 | H13: US | I13: 0 | J13: US | K13: M | L13: =_xlfn.XLOOKUP($D13,mapping!$B$2:$B$124,mapping!$A$2:$A$124,,0) -> Data Analyst | M13: =_xlfn.XLOOKUP($C13,mapping!$J$2:$J$5,mapping!$K$2:$K$5,,0) -> Full-Time | N13: =_xlfn.XLOOKUP($B13,mapping!$G$2:$G$5,mapping!$H$2:$H$5,,0) -> Senior | O13: =_xlfn.XLOOKUP($J13,mapping!$D$2:$D$56,mapping!$E$2:$E$56,,0) -> United States | P13: =_xlfn.XLOOKUP($K13,mapping!$P$2:$P$4,mapping!$Q$2:$Q$4,,0) -> Medium | Q13: =_xlfn.XLOOKUP($I13,mapping!$M$2:$M$4,mapping!$N$2:$N$4,,0) -> On-site
... A5001: 2023 | B5001: SE | C5001: FT | D5001: Machine Learning Engineer | E5001: 176000 | F5001: USD | G5001: 176000 | H5001: US | I5001: 0 | J5001: US | K5001: M | L5001: =_xlfn.XLOOKUP($D5001,mapping!$B$2:$B$124,mapping!$A$2:$A$124,,0) -> Machine Learning Engineer | M5001: =_xlfn.XLOOKUP($C5001,mapping!$J$2:$J$5,mapping!$K$2:$K$5,,0) -> Full-Time | N5001: =_xlfn.XLOOKUP($B5001,mapping!$G$2:$G$5,mapping!$H$2:$H$5,,0) -> Senior | O5001: =_xlfn.XLOOKUP($J5001,mapping!$D$2:$D$56,mapping!$E$2:$E$56,,0) -> United States | P5001: =_xlfn.XLOOKUP($K5001,mapping!$P$2:$P$4,mapping!$Q$2:$Q$4,,0) -> Medium | Q5001: =_xlfn.XLOOKUP($I5001,mapping!$M$2:$M$4,mapping!$N$2:$N$4,,0) -> On-site

Sheet mapping
A1: job_title_short | B1: job_title | D1: Code | E1: Country | G1: Level | H1: New Level | J1: Schedule | K1: New Schedule | M1: remote_ratio | N1: job_type | P1: company | Q1: new_company
A2: Data Engineer | B2: Data Engineer | D2: US | E2: United States | G2: MI | H2: Mid-Level | J2: FT | K2: Full-Time | M2: 0 | N2: On-site | P2: L | Q2: Large
A3: Data Engineer | B3: Data Developer | D3: GB | E3: United Kingdom | G3: SE | H3: Senior | J3: PT | K3: Part-Time | M3: 50 | N3: Hybrid | P3: M | Q3: Medium
A4: Data Engineer | B4: Data Science Engineer | D4: CA | E4: Canada | G4: EX | H4: Executive | J4: CT | K4: Contract | M4: 100 | N4: Remote | P4: S | Q4: Small
A5: Data Engineer | B5: ETL Developer | D5: AU | E5: Australia | G5: EN | H5: Junior | J5: FL | K5: Full-Time
A6: Data Engineer | B6: Data Operations Specialist | D6: PT | E6: Portugal
A7: Data Engineer | B7: Data Infrastructure Engineer | D7: IE | E7: Ireland
A8: Data Engineer | B8: Data Integration Specialist | D8: DE | E8: Germany
A9: Data Engineer | B9: Data Operations Engineer | D9: ES | E9: Spain
A10: Data Engineer | B10: MLOps Engineer | D10: NL | E10: Netherlands
A11: Data Engineer | B11: Data Operations Analyst | D11: IN | E11: India
A12: Data Engineer | B12: Data Integration Engineer | D12: IT | E12: Italy
A13: Data Engineer | B13: Data Operations Associate | D13: FR | E13: France
A14: Data Engineer | B14: ETL Engineer | D14: PL | E14: Poland
A15: Data Engineer | B15: Big Data Engineer | D15: UA | E15: Ukraine
A16: Data Engineer | B16: Data Integration Developer | D16: VN | E16: Vietnam
A17: Data Engineer | B17: Data Quality Engineer | D17: MX | E17: Mexico
... A56: Machine Learning Engineer | B56: Machine Learning Scientist | D56: RU | E56: Russia
A57: Machine Learning Engineer | B57: Machine Learning Infrastructure Engineer
A58: Machine Learning Engineer | B58: AI Engineer
A59: Machine Learning Engineer | B59: AI Architect
A60: Machine Learning Engineer | B60: AI Scientist
A61: Machine Learning Engineer | B61: NLP Engineer
A62: Machine Learning Engineer | B62: Prompt Engineer
A63: Machine Learning Engineer | B63: Head of Machine Learning
A64: Machine Learning Engineer | B64: Machine Learning Research Engineer
A65: Machine Learning Engineer | B65: Machine Learning Developer
A66: Machine Learning Engineer | B66: Applied Machine Learning Scientist
A67: Machine Learning Engineer | B67: Deep Learning Engineer
A68: Machine Learning Engineer | B68: Lead Machine Learning Engineer
... A124: Others | B124: Autonomous Vehicle Technician

Sheet intro_analysis
A1: Years | C1: Experience | E1: Schedule | G1: Jobs | I1: Currency | K1: Residence | M1: Location | O1: Comp. Size | Q1: Remote ratio | T1: Jobs Ordered | W1: Jobs Short | Z1: Location Ordered
A2: {=_xlfn._xlws.SORT(_xlfn.UNIQUE(jobs[work_year]),1,-1)} -> 2024 | B2: =COUNTIF(jobs[work_year], $A2) -> 1445 | C2: {=_xlfn.UNIQUE(jobs[job_exp])} -> Mid-Level | D2: =COUNTIF(jobs[job_exp], $C2) -> 1215 | E2: {=_xlfn.UNIQUE(jobs[job_sch])} -> Full-Time | F2: =COUNTIF(jobs[],$E2) -> 4981 | G2: {=_xlfn.UNIQUE(jobs[job_title])} -> Data Analyst | H2: =COUNTIF(jobs[job_title], $G2) -> 735 | I2: {=_xlfn.UNIQUE(jobs[salary_currency])} -> USD | J2: =COUNTIF(jobs[salary_currency],$I2) -> 4623 | K2: {=_xlfn.UNIQUE(jobs[employee_residence])} -> AU | L2: =COUNTIF(jobs[employee_residence], $K2) -> 14 | M2: {=_xlfn.UNIQUE(jobs[job_location])} -> Australia | N2: =COUNTIF(jobs[job_location], $M2) -> 16 | O2: {=_xlfn.UNIQUE(jobs[job_company_size])} -> Medium | P2: =COUNTIF(jobs[job_company_size], $O2) -> 4603 | Q2: {=_xlfn.UNIQUE(jobs[job_type])} -> On-site | R2: =COUNTIF(jobs[job_type], $Q2) -> 3317 | T2: {=_xlfn._xlws.SORT(G2:H124,2,-1)} -> Data Engineer | U2: 1067 | W2: {=_xlfn.UNIQUE(jobs[job_title_short])} -> Data Analyst | X2: =COUNTIF(jobs[job_title_short],$W2) -> 778 | Z2: {=_xlfn._xlws.SORT(M2:N56,2,-1)} -> United States | AA2: 4402
A3: 2023 | B3: =COUNTIF(jobs[work_year], $A3) -> 2921 | C3: Senior | D3: =COUNTIF(jobs[job_exp], $C3) -> 3248 | E3: Part-Time | F3: =COUNTIF(jobs[],$E3) -> 9 | G3: Machine Learning Engineer | H3: =COUNTIF(jobs[job_title], $G3) -> 511 | I3: EUR | J3: =COUNTIF(jobs[salary_currency],$I3) -> 151 | K3: US | L3: =COUNTIF(jobs[employee_residence], $K3) -> 4388 | M3: United States | N3: =COUNTIF(jobs[job_location], $M3) -> 4402 | O3: Large | P3: =COUNTIF(jobs[job_company_size], $O3) -> 335 | Q3: Remote | R3: =COUNTIF(jobs[job_type], $Q3) -> 1597 | T3: Data Scientist | U3: 1025 | W3: Machine Learning Engineer | X3: =COUNTIF(jobs[job_title_short],$W3) -> 732 | Z3: United Kingdom | AA3: 202
A4: 2022 | B4: =COUNTIF(jobs[work_year], $A4) -> 530 | C4: Executive | D4: =COUNTIF(jobs[job_exp], $C4) -> 162 | E4: Contract | F4: =COUNTIF(jobs[],$E4) -> 10 | G4: Data Scientist | H4: =COUNTIF(jobs[job_title], $G4) -> 1025 | I4: GBP | J4: =COUNTIF(jobs[salary_currency],$I4) -> 171 | K4: IE | L4: =COUNTIF(jobs[employee_residence], $K4) -> 7 | M4: Ireland | N4: =COUNTIF(jobs[job_location], $M4) -> 7 | O4: Small | P4: =COUNTIF(jobs[job_company_size], $O4) -> 62 | Q4: Hybrid | R4: =COUNTIF(jobs[job_type], $Q4) -> 86 | T4: Data Analyst | U4: 735 | W4: Data Scientist | X4: =COUNTIF(jobs[job_title_short],$W4) -> 1167 | Z4: Canada | AA4: 115
A5: 2021 | B5: =COUNTIF(jobs[work_year], $A5) -> 79 | C5: Junior | D5: =COUNTIF(jobs[job_exp], $C5) -> 375 | G5: Research Engineer | H5: =COUNTIF(jobs[job_title], $G5) -> 90 | I5: INR | J5: =COUNTIF(jobs[salary_currency],$I5) -> 15 | K5: PT | L5: =COUNTIF(jobs[employee_residence], $K5) -> 13 | M5: Portugal | N5: =COUNTIF(jobs[job_location], $M5) -> 12 | T5: Machine Learning Engineer | U5: 511 | W5: Researcher | X5: =COUNTIF(jobs[job_title_short],$W5) -> 294 | Z5: Spain | AA5: 52
A6: 2020 | B6: =COUNTIF(jobs[work_year], $A6) -> 25 | G6: Data Engineer | H6: =COUNTIF(jobs[job_title], $G6) -> 1067 | I6: PLN | J6: =COUNTIF(jobs[salary_currency],$I6) -> 3 | K6: GB | L6: =COUNTIF(jobs[employee_residence], $K6) -> 198 | M6: United Kingdom | N6: =COUNTIF(jobs[job_location], $M6) -> 202 | T6: Research Scientist | U6: 153 | W6: Data Engineer | X6: =COUNTIF(jobs[job_title_short],$W6) -> 1151 | Z6: Germany | AA6: 34
G7: Machine Learning Infrastructure Engineer | H7: =COUNTIF(jobs[job_title], $G7) -> 15 | I7: DKK | J7: =COUNTIF(jobs[salary_currency],$I7) -> 2 | K7: DE | L7: =COUNTIF(jobs[employee_residence], $K7) -> 34 | M7: Germany | N7: =COUNTIF(jobs[job_location], $M7) -> 34 | T7: Analytics Engineer | U7: 127 | W7: Analytics Engineer | X7: =COUNTIF(jobs[job_title_short],$W7) -> 133 | Z7: France | AA7: 20
G8: Analytics Engineer | H8: =COUNTIF(jobs[job_title], $G8) -> 127 | I8: CAD | J8: =COUNTIF(jobs[salary_currency],$I8) -> 20 | K8: IN | L8: =COUNTIF(jobs[employee_residence], $K8) -> 21 | M8: India | N8: =COUNTIF(jobs[job_location], $M8) -> 16 | T8: Applied Scientist | U8: 125 | W8: Business Intelligence | X8: =COUNTIF(jobs[job_title_short],$W8) -> 233 | Z8: Australia | AA8: 16
G9: AI Research Engineer | H9: =COUNTIF(jobs[job_title], $G9) -> 2 | I9: PHP | J9: =COUNTIF(jobs[salary_currency],$I9) -> 1 | K9: ES | L9: =COUNTIF(jobs[employee_residence], $K9) -> 52 | M9: Spain | N9: =COUNTIF(jobs[job_location], $M9) -> 52 | T9: Data Architect | U9: 117 | W9: Applied Scientist | X9: =COUNTIF(jobs[job_title_short],$W9) -> 125 | Z9: India | AA9: 16
G10: Research Scientist | H10: =COUNTIF(jobs[job_title], $G10) -> 153 | I10: NZD | J10: =COUNTIF(jobs[salary_currency],$I10) -> 1 | K10: NL | L10: =COUNTIF(jobs[employee_residence], $K10) -> 9 | M10: Netherlands | N10: =COUNTIF(jobs[job_location], $M10) -> 11 | T10: Business Intelligence Engineer | U10: 92 | W10: Data Manager | X10: =COUNTIF(jobs[job_title_short],$W10) -> 186 | Z10: Portugal | AA10: 12
G11: BI Analyst | H11: =COUNTIF(jobs[job_title], $G11) -> 12 | I11: MXN | J11: =COUNTIF(jobs[salary_currency],$I11) -> 1 | K11: CA | L11: =COUNTIF(jobs[employee_residence], $K11) -> 116 | M11: Canada | N11: =COUNTIF(jobs[job_location], $M11) -> 115 | T11: Research Engineer | U11: 90 | W11: Data Specialist | X11: =COUNTIF(jobs[job_title_short],$W11) -> 46 | Z11: Netherlands | AA11: 11
G12: ML Engineer | H12: =COUNTIF(jobs[job_title], $G12) -> 50 | I12: CHF | J12: =COUNTIF(jobs[salary_currency],$I12) -> 1 | K12: NG | L12: =COUNTIF(jobs[employee_residence], $K12) -> 5 | M12: Ukraine | N12: =COUNTIF(jobs[job_location], $M12) -> 2 | T12: Data Science | U12: 74 | W12: Data Architect | X12: =COUNTIF(jobs[job_title_short],$W12) -> 117 | Z12: Brazil | AA12: 9
G13: Business Intelligence Analyst | H13: =COUNTIF(jobs[job_title], $G13) -> 44 | I13: AUD | J13: =COUNTIF(jobs[salary_currency],$I13) -> 4 | K13: UA | L13: =COUNTIF(jobs[employee_residence], $K13) -> 3 | M13: Italy | N13: =COUNTIF(jobs[job_location], $M13) -> 5 | T13: Data Manager | U13: 70 | W13: Computer Vision Engineer | X13: =COUNTIF(jobs[job_title_short],$W13) -> 13 | Z13: Ireland | AA13: 7
G14: AI Engineer | H14: =COUNTIF(jobs[job_title], $G14) -> 43 | I14: JPY | J14: =COUNTIF(jobs[salary_currency],$I14) -> 1 | K14: IT | L14: =COUNTIF(jobs[employee_residence], $K14) -> 6 | M14: Vietnam | N14: =COUNTIF(jobs[job_location], $M14) -> 3 | T14: ML Engineer | U14: 50 | W14: Software Engineer | X14: =COUNTIF(jobs[job_title_short],$W14) -> 11 | Z14: Mexico | AA14: 6
G15: Research Analyst | H15: =COUNTIF(jobs[job_title], $G15) -> 39 | I15: SGD | J15: =COUNTIF(jobs[salary_currency],$I15) -> 2 | K15: VN | L15: =COUNTIF(jobs[employee_residence], $K15) -> 5 | M15: Mexico | N15: =COUNTIF(jobs[job_location], $M15) -> 6 | T15: Machine Learning Scientist | U15: 46 | W15: Others | X15: =COUNTIF(jobs[job_title_short],$W15) -> 6 | Z15: Poland | AA15: 6
G16: Staff Data Analyst | H16: =COUNTIF(jobs[job_title], $G16) -> 2 | I16: THB | J16: =COUNTIF(jobs[salary_currency],$I16) -> 2 | K16: MX | L16: =COUNTIF(jobs[employee_residence], $K16) -> 5 | M16: Poland | N16: =COUNTIF(jobs[job_location], $M16) -> 6 | T16: Business Intelligence Analyst | U16: 44 | W16: Cloud Engineer | X16: =COUNTIF(jobs[job_title_short],$W16) -> 8 | Z16: Italy | AA16: 5
G17: Data Infrastructure Engineer | H17: =COUNTIF(jobs[job_title], $G17) -> 6 | I17: BRL | J17: =COUNTIF(jobs[salary_currency],$I17) -> 1 | K17: PL | L17: =COUNTIF(jobs[employee_residence], $K17) -> 6 | M17: Egypt | N17: =COUNTIF(jobs[job_location], $M17) -> 4 | T17: AI Engineer | U17: 43 | W17: Total | X17: =SUM(X2:X16) -> 5000 | Z17: Colombia | AA17: 5
G18: Data Operations Specialist | H18: =COUNTIF(jobs[job_title], $G18) -> 7 | I18: TRY | J18: =COUNTIF(jobs[salary_currency],$I18) -> 1 | K18: AR | L18: =COUNTIF(jobs[employee_residence], $K18) -> 5 | M18: Denmark | N18: =COUNTIF(jobs[job_location], $M18) -> 2 | T18: Research Analyst | U18: 39 | Z18: Lithuania | AA18: 5
G19: Machine Learning Scientist | H19: =COUNTIF(jobs[job_title], $G19) -> 46 | K19: EG | L19: =COUNTIF(jobs[employee_residence], $K19) -> 5 | M19: Honduras | N19: =COUNTIF(jobs[job_location], $M19) -> 1 | T19: Data Science Manager | U19: 38 | Z19: South Africa | AA19: 5
G20: Applied Scientist | H20: =COUNTIF(jobs[job_title], $G20) -> 125 | K20: DK | L20: =COUNTIF(jobs[employee_residence], $K20) -> 2 | M20: Colombia | N20: =COUNTIF(jobs[job_location], $M20) -> 5 | T20: BI Developer | U20: 27 | Z20: Egypt | AA20: 4
G21: BI Developer | H21: =COUNTIF(jobs[job_title], $G21) -> 27 | K21: HN | L21: =COUNTIF(jobs[employee_residence], $K21) -> 1 | M21: Armenia | N21: =COUNTIF(jobs[job_location], $M21) -> 1 | T21: Data Science Consultant | U21: 27 | Z21: Slovenia | AA21: 4
G22: Machine Learning Researcher | H22: =COUNTIF(jobs[job_title], $G22) -> 8 | K22: CO | L22: =COUNTIF(jobs[employee_residence], $K22) -> 5 | M22: Central African Republic | N22: =COUNTIF(jobs[job_location], $M22) -> 2 | T22: Business Intelligence | U22: 22 | Z22: Estonia | AA22: 4
G23: Data Science | H23: =COUNTIF(jobs[job_title], $G23) -> 74 | K23: AM | L23: =COUNTIF(jobs[employee_residence], $K23) -> 1 | M23: Philippines | N23: =COUNTIF(jobs[job_location], $M23) -> 2 | T23: Data Specialist | U23: 21 | Z23: Nigeria | AA23: 4
G24: Data Science Manager | H24: =COUNTIF(jobs[job_title], $G24) -> 38 | K24: CF | L24: =COUNTIF(jobs[employee_residence], $K24) -> 2 | M24: Lithuania | N24: =COUNTIF(jobs[job_location], $M24) -> 5 | T24: Head of Data | U24: 21 | Z24: Vietnam | AA24: 3
G25: Data Specialist | H25: =COUNTIF(jobs[job_title], $G25) -> 21 | K25: PH | L25: =COUNTIF(jobs[employee_residence], $K25) -> 4 | M25: Russia | N25: =COUNTIF(jobs[job_location], $M25) -> 1 | T25: Business Intelligence Developer | U25: 17 | Z25: Argentina | AA25: 3
G26: NLP Engineer | H26: =COUNTIF(jobs[job_title], $G26) -> 7 | K26: LT | L26: =COUNTIF(jobs[employee_residence], $K26) -> 5 | M26: New Zealand | N26: =COUNTIF(jobs[job_location], $M26) -> 1 | T26: Data Analytics Manager | U26: 16 | Z26: United Arab Emirates | AA26: 3
G27: Business Intelligence Engineer | H27: =COUNTIF(jobs[job_title], $G27) -> 92 | K27: RU | L27: =COUNTIF(jobs[employee_residence], $K27) -> 1 | M27: Japan | N27: =COUNTIF(jobs[job_location], $M27) -> 2 | T27: Machine Learning Infrastructure Engineer | U27: 15 | Z27: Turkey | AA27: 3
G28: Data Architect | H28: =COUNTIF(jobs[job_title], $G28) -> 117 | K28: NZ | L28: =COUNTIF(jobs[employee_residence], $K28) -> 1 | M28: France | N28: =COUNTIF(jobs[job_location], $M28) -> 20 | T28: Computer Vision Engineer | U28: 13 | Z28: Ukraine | AA28: 2
G29: Data Science Practitioner | H29: =COUNTIF(jobs[job_title], $G29) -> 6 | K29: JP | L29: =COUNTIF(jobs[employee_residence], $K29) -> 3 | M29: South Africa | N29: =COUNTIF(jobs[job_location], $M29) -> 5 | T29: BI Analyst | U29: 12 | Z29: Denmark | AA29: 2
G30: Computer Vision Engineer | H30: =COUNTIF(jobs[job_title], $G30) -> 13 | K30: FR | L30: =COUNTIF(jobs[employee_residence], $K30) -> 21 | M30: Slovenia | N30: =COUNTIF(jobs[job_location], $M30) -> 4 | T30: Data Modeler | U30: 12 | Z30: Central African Republic | AA30: 2
... G56: AI Architect | H56: =COUNTIF(jobs[job_title], $G56) -> 10 | K56: IQ | L56: =COUNTIF(jobs[employee_residence], $K56) -> 1 | M56: Iraq | N56: =COUNTIF(jobs[job_location], $M56) -> 1 | T56: Data Operations Engineer | U56: 5 | Z56: Iraq | AA56: 1
G57: Data Science Consultant | H57: =COUNTIF(jobs[job_title], $G57) -> 27 | T57: Robotics Software Engineer | U57: 5
G58: ETL Developer | H58: =COUNTIF(jobs[job_title], $G58) -> 9 | T58: MLOps Engineer | U58: 5
G59: Data Operations Engineer | H59: =COUNTIF(jobs[job_title], $G59) -> 5 | T59: Head of Machine Learning | U59: 5
G60: Data Quality Engineer | H60: =COUNTIF(jobs[job_title], $G60) -> 1 | T60: Cloud Database Engineer | U60: 5
G61: Applied Machine Learning Scientist | H61: =COUNTIF(jobs[job_title], $G61) -> 3 | T61: Applied Data Scientist | U61: 5
G62: Data Analyst Lead | H62: =COUNTIF(jobs[job_title], $G62) -> 1 | T62: Data Operations Analyst | U62: 4
G63: Machine Learning Operations Engineer | H63: =COUNTIF(jobs[job_title], $G63) -> 1 | T63: Machine Learning Research Engineer | U63: 4
G64: Machine Learning Research Engineer | H64: =COUNTIF(jobs[job_title], $G64) -> 4 | T64: Data Analytics Consultant | U64: 4
G65: Robotics Engineer | H65: =COUNTIF(jobs[job_title], $G65) -> 2 | T65: Data Visualization Specialist | U65: 4
...

Sheet calculator
A1: year | B1: count | D1: job_title_short | E1: median salary | F1: median salary | H1: job | I1: job_count | K1: ordered | N1: type rate
A2: {=_xlfn._xlws.SORT(_xlfn.UNIQUE(jobs[work_year]),1,-1)} -> 2024 | B2: =COUNTIF(jobs[work_year], $A2) -> 1445 | D2: Data Engineer | E2: {=IF(job<>$D2,MEDIAN(IF(jobs[job_title_short]=$D2,jobs[salary_in_usd],FALSE)),FALSE)} -> 136600 | F2: {=IF(job=$D2,MEDIAN(IF(jobs[job_title_short]=$D2,jobs[salary_in_usd],FALSE)),FALSE)} -> FALSE | H2: {=_xlfn.UNIQUE(jobs[job_title_short])} -> Data Analyst | I2: {=COUNT(IF((jobs[job_title_short]=$H2) * (jobs[work_year]=year),year,""))} -> 7 | K2: {=_xlfn._xlws.SORT(H2:I16,2,-1)} -> Data Scientist | L2: 20 | N2: On-site | O2: {=SUM(IF((jobs[job_type]=$N2) * (jobs[work_year]=year),1,"")) / _xlfn.XLOOKUP(year,$A$2:$A$6,$B$2:$B$6,,0)} -> 0.088607595
A3: 2023 | B3: =COUNTIF(jobs[work_year], $A3) -> 2921 | D3: Data Scientist | E3: {=IF(job<>$D3,MEDIAN(IF(jobs[job_title_short]=$D3,jobs[salary_in_usd],FALSE)),FALSE)} -> 150000 | F3: {=IF(job=$D3,MEDIAN(IF(jobs[job_title_short]=$D3,jobs[salary_in_usd],FALSE)),FALSE)} -> FALSE | H3: Machine Learning Engineer | I3: {=COUNT(IF((jobs[job_title_short]=$H3) * (jobs[work_year]=year),year,""))} -> 16 | K3: Machine Learning Engineer | L3: 16 | N3: Remote | O3: {=SUM(IF((jobs[job_type]=$N3) * (jobs[work_year]=year),1,"")) / _xlfn.XLOOKUP(year,$A$2:$A$6,$B$2:$B$6,,0)} -> 0.51898734
A4: 2022 | B4: =COUNTIF(jobs[work_year], $A4) -> 530 | D4: Data Analyst | E4: {=IF(job<>$D4,MEDIAN(IF(jobs[job_title_short]=$D4,jobs[salary_in_usd],FALSE)),FALSE)} -> 100000 | F4: {=IF(job=$D4,MEDIAN(IF(jobs[job_title_short]=$D4,jobs[salary_in_usd],FALSE)),FALSE)} -> FALSE | H4: Data Scientist | I4: {=COUNT(IF((jobs[job_title_short]=$H4) * (jobs[work_year]=year),year,""))} -> 20 | K4: Data Engineer | L4: 15 | N4: Hybrid | O4: {=SUM(IF((jobs[job_type]=$N4) * (jobs[work_year]=year),1,"")) / _xlfn.XLOOKUP(year,$A$2:$A$6,$B$2:$B$6,,0)} -> 0.39240506
A5: 2021 | B5: =COUNTIF(jobs[work_year], $A5) -> 79 | D5: Machine Learning Engineer | E5: {=IF(job<>$D5,MEDIAN(IF(jobs[job_title_short]=$D5,jobs[salary_in_usd],FALSE)),FALSE)} -> 180000 | F5: {=IF(job=$D5,MEDIAN(IF(jobs[job_title_short]=$D5,jobs[salary_in_usd],FALSE)),FALSE)} -> FALSE | H5: Researcher | I5: {=COUNT(IF((jobs[job_title_short]=$H5) * (jobs[work_year]=year),year,""))} -> 6 | K5: Data Analyst | L5: 7
A6: 2020 | B6: =COUNTIF(jobs[work_year], $A6) -> 25 | D6: Applied Scientist | E6: {=IF(job<>$D6,MEDIAN(IF(jobs[job_title_short]=$D6,jobs[salary_in_usd],FALSE)),FALSE)} -> 184000 | F6: {=IF(job=$D6,MEDIAN(IF(jobs[job_title_short]=$D6,jobs[salary_in_usd],FALSE)),FALSE)} -> FALSE | H6: Data Engineer | I6: {=COUNT(IF((jobs[job_title_short]=$H6) * (jobs[work_year]=year),year,""))} -> 15 | K6: Researcher | L6: 6
D7: Researcher | E7: {=IF(job<>$D7,MEDIAN(IF(jobs[job_title_short]=$D7,jobs[salary_in_usd],FALSE)),FALSE)} -> 165250 | F7: {=IF(job=$D7,MEDIAN(IF(jobs[job_title_short]=$D7,jobs[salary_in_usd],FALSE)),FALSE)} -> FALSE | H7: Analytics Engineer | I7: {=COUNT(IF((jobs[job_title_short]=$H7) * (jobs[work_year]=year),year,""))} -> 2 | K7: Data Manager | L7: 4
A8: =_xlfn.XLOOKUP(year,calculator!A2:A6,calculator!B2:B6,,0) -> 79 | D8: Analytics Engineer | E8: {=IF(job<>$D8,MEDIAN(IF(jobs[job_title_short]=$D8,jobs[salary_in_usd],FALSE)),FALSE)} -> 136675 | F8: {=IF(job=$D8,MEDIAN(IF(jobs[job_title_short]=$D8,jobs[salary_in_usd],FALSE)),FALSE)} -> FALSE | H8: Business Intelligence | I8: {=COUNT(IF((jobs[job_title_short]=$H8) * (jobs[work_year]=year),year,""))} -> 2 | K8: Analytics Engineer | L8: 2
D9: Data Architect | E9: {=IF(job<>$D9,MEDIAN(IF(jobs[job_title_short]=$D9,jobs[salary_in_usd],FALSE)),FALSE)} -> FALSE | F9: {=IF(job=$D9,MEDIAN(IF(jobs[job_title_short]=$D9,jobs[salary_in_usd],FALSE)),FALSE)} -> 160000 | H9: Applied Scientist | I9: {=COUNT(IF((jobs[job_title_short]=$H9) * (jobs[work_year]=year),year,""))} -> 0 | K9: Business Intelligence | L9: 2
D10: Business Intelligence | E10: {=IF(job<>$D10,MEDIAN(IF(jobs[job_title_short]=$D10,jobs[salary_in_usd],FALSE)),FALSE)} -> 118800 | F10: {=IF(job=$D10,MEDIAN(IF(jobs[job_title_short]=$D10,jobs[salary_in_usd],FALSE)),FALSE)} -> FALSE | H10: Data Manager | I10: {=COUNT(IF((jobs[job_title_short]=$H10) * (jobs[work_year]=year),year,""))} -> 4 | K10: Data Specialist | L10: 2
D11: Data Manager | E11: {=IF(job<>$D11,MEDIAN(IF(jobs[job_title_short]=$D11,jobs[salary_in_usd],FALSE)),FALSE)} -> 140000 | F11: {=IF(job=$D11,MEDIAN(IF(jobs[job_title_short]=$D11,jobs[salary_in_usd],FALSE)),FALSE)} -> FALSE | H11: Data Specialist | I11: {=COUNT(IF((jobs[job_title_short]=$H11) * (jobs[work_year]=year),year,""))} -> 2 | K11: Computer Vision Engineer | L11: 2
D12: Data Specialist | E12: {=IF(job<>$D12,MEDIAN(IF(jobs[job_title_short]=$D12,jobs[salary_in_usd],FALSE)),FALSE)} -> 108333 | F12: {=IF(job=$D12,MEDIAN(IF(jobs[job_title_short]=$D12,jobs[salary_in_usd],FALSE)),FALSE)} -> FALSE | H12: Data Architect | I12: {=COUNT(IF((jobs[job_title_short]=$H12) * (jobs[work_year]=year),year,""))} -> 1 | K12: Data Architect | L12: 1
D13: Computer Vision Engineer | E13: {=IF(job<>$D13,MEDIAN(IF(jobs[job_title_short]=$D13,jobs[salary_in_usd],FALSE)),FALSE)} -> 184590 | F13: {=IF(job=$D13,MEDIAN(IF(jobs[job_title_short]=$D13,jobs[salary_in_usd],FALSE)),FALSE)} -> FALSE | H13: Computer Vision Engineer | I13: {=COUNT(IF((jobs[job_title_short]=$H13) * (jobs[work_year]=year),year,""))} -> 2 | K13: Software Engineer | L13: 1
D14: Software Engineer | E14: {=IF(job<>$D14,MEDIAN(IF(jobs[job_title_short]=$D14,jobs[salary_in_usd],FALSE)),FALSE)} -> 198000 | F14: {=IF(job=$D14,MEDIAN(IF(jobs[job_title_short]=$D14,jobs[salary_in_usd],FALSE)),FALSE)} -> FALSE | H14: Software Engineer | I14: {=COUNT(IF((jobs[job_title_short]=$H14) * (jobs[work_year]=year),year,""))} -> 1 | K14: Cloud Engineer | L14: 1
D15: Cloud Engineer | E15: {=IF(job<>$D15,MEDIAN(IF(jobs[job_title_short]=$D15,jobs[salary_in_usd],FALSE)),FALSE)} -> 104250 | F15: {=IF(job=$D15,MEDIAN(IF(jobs[job_title_short]=$D15,jobs[salary_in_usd],FALSE)),FALSE)} -> FALSE | H15: Others | I15: {=COUNT(IF((jobs[job_title_short]=$H15) * (jobs[work_year]=year),year,""))} -> 0 | K15: Applied Scientist | L15: 0
D16: Others | E16: {=IF(job<>$D16,MEDIAN(IF(jobs[job_title_short]=$D16,jobs[salary_in_usd],FALSE)),FALSE)} -> 165192 | F16: {=IF(job=$D16,MEDIAN(IF(jobs[job_title_short]=$D16,jobs[salary_in_usd],FALSE)),FALSE)} -> FALSE | H16: Cloud Engineer | I16: {=COUNT(IF((jobs[job_title_short]=$H16) * (jobs[work_year]=year),year,""))} -> 1 | K16: Others | L16: 0
D19: =_xlfn.XLOOKUP(job,calculator!D2:D16,calculator!F2:F16,,0) -> 160000
D21: job_title_short | E21: median salary | G21: median_salary_ordered
D22: Data Engineer | E22: {=MEDIAN(IF(jobs[job_title_short]=$D22,jobs[salary_in_usd],FALSE))} -> 136600 | G22: {=_xlfn._xlws.SORT(D22:E36,2,1)} -> Data Analyst | H22: 100000 | I22: =IF(job<>$G22,$H22,FALSE) -> 100000 | J22: =IF(job=$G22,$H22,FALSE) -> FALSE
D23: Data Scientist | E23: {=MEDIAN(IF(jobs[job_title_short]=$D23,jobs[salary_in_usd],FALSE))} -> 150000 | G23: Cloud Engineer | H23: 104250 | I23: =IF(job<>$G23,$H23,FALSE) -> 104250 | J23: =IF(job=$G23,$H23,FALSE) -> FALSE
D24: Data Analyst | E24: {=MEDIAN(IF(jobs[job_title_short]=$D24,jobs[salary_in_usd],FALSE))} -> 100000 | G24: Data Specialist | H24: 108333 | I24: =IF(job<>$G24,$H24,FALSE) -> 108333 | J24: =IF(job=$G24,$H24,FALSE) -> FALSE
D25: Machine Learning Engineer | E25: {=MEDIAN(IF(jobs[job_title_short]=$D25,jobs[salary_in_usd],FALSE))} -> 180000 | G25: Business Intelligence | H25: 118800 | I25: =IF(job<>$G25,$H25,FALSE) -> 118800 | J25: =IF(job=$G25,$H25,FALSE) -> FALSE
D26: Applied Scientist | E26: {=MEDIAN(IF(jobs[job_title_short]=$D26,jobs[salary_in_usd],FALSE))} -> 184000 | G26: Data Engineer | H26: 136600 | I26: =IF(job<>$G26,$H26,FALSE) -> 136600 | J26: =IF(job=$G26,$H26,FALSE) -> FALSE
D27: Researcher | E27: {=MEDIAN(IF(jobs[job_title_short]=$D27,jobs[salary_in_usd],FALSE))} -> 165250 | G27: Analytics Engineer | H27: 136675 | I27: =IF(job<>$G27,$H27,FALSE) -> 136675 | J27: =IF(job=$G27,$H27,FALSE) -> FALSE
D28: Analytics Engineer | E28: {=MEDIAN(IF(jobs[job_title_short]=$D28,jobs[salary_in_usd],FALSE))} -> 136675 | G28: Data Manager | H28: 140000 | I28: =IF(job<>$G28,$H28,FALSE) -> 140000 | J28: =IF(job=$G28,$H28,FALSE) -> FALSE
D29: Data Architect | E29: {=MEDIAN(IF(jobs[job_title_short]=$D29,jobs[salary_in_usd],FALSE))} -> 160000 | G29: Data Scientist | H29: 150000 | I29: =IF(job<>$G29,$H29,FALSE) -> 150000 | J29: =IF(job=$G29,$H29,FALSE) -> FALSE
D30: Business Intelligence | E30: {=MEDIAN(IF(jobs[job_title_short]=$D30,jobs[salary_in_usd],FALSE))} -> 118800 | G30: Data Architect | H30: 160000 | I30: =IF(job<>$G30,$H30,FALSE) -> FALSE | J30: =IF(job=$G30,$H30,FALSE) -> 160000
D31: Data Manager | E31: {=MEDIAN(IF(jobs[job_title_short]=$D31,jobs[salary_in_usd],FALSE))} -> 140000 | G31: Others | H31: 165192 | I31: =IF(job<>$G31,$H31,FALSE) -> 165192 | J31: =IF(job=$G31,$H31,FALSE) -> FALSE
D32: Data Specialist | E32: {=MEDIAN(IF(jobs[job_title_short]=$D32,jobs[salary_in_usd],FALSE))} -> 108333 | G32: Researcher | H32: 165250 | I32: =IF(job<>$G32,$H32,FALSE) -> 165250 | J32: =IF(job=$G32,$H32,FALSE) -> FALSE
D33: Computer Vision Engineer | E33: {=MEDIAN(IF(jobs[job_title_short]=$D33,jobs[salary_in_usd],FALSE))} -> 184590 | G33: Machine Learning Engineer | H33: 180000 | I33: =IF(job<>$G33,$H33,FALSE) -> 180000 | J33: =IF(job=$G33,$H33,FALSE) -> FALSE
D34: Software Engineer | E34: {=MEDIAN(IF(jobs[job_title_short]=$D34,jobs[salary_in_usd],FALSE))} -> 198000 | G34: Applied Scientist | H34: 184000 | I34: =IF(job<>$G34,$H34,FALSE) -> 184000 | J34: =IF(job=$G34,$H34,FALSE) -> FALSE
... D36: Others | E36: {=MEDIAN(IF(jobs[job_title_short]=$D36,jobs[salary_in_usd],FALSE))} -> 165192 | G36: Software Engineer | H36: 198000 | I36: =IF(job<>$G36,$H36,FALSE) -> 198000 | J36: =IF(job=$G36,$H36,FALSE) -> FALSE

Sheet Country
A1: country | B1: count | E1: country | F1: count
A2: {=_xlfn.UNIQUE(jobs[job_location])} -> Australia | B2: =COUNTIFS(jobs[job_location],$A2,jobs[work_year],year) -> 0 | E2: {=_xlfn._xlws.SORT(A2:B56,2,-1)} -> United States | F2: 30
A3: United States | B3: =COUNTIFS(jobs[job_location],$A3,jobs[work_year],year) -> 30 | E3: Germany | F3: 8
A4: Ireland | B4: =COUNTIFS(jobs[job_location],$A4,jobs[work_year],year) -> 0 | E4: United Kingdom | F4: 6
A5: Portugal | B5: =COUNTIFS(jobs[job_location],$A5,jobs[work_year],year) -> 1 | E5: India | F5: 6
A6: United Kingdom | B6: =COUNTIFS(jobs[job_location],$A6,jobs[work_year],year) -> 6 | E6: Canada | F6: 4
A7: Germany | B7: =COUNTIFS(jobs[job_location],$A7,jobs[work_year],year) -> 8 | E7: France | F7: 4
A8: India | B8: =COUNTIFS(jobs[job_location],$A8,jobs[work_year],year) -> 6 | E8: Spain | F8: 2
A9: Spain | B9: =COUNTIFS(jobs[job_location],$A9,jobs[work_year],year) -> 2 | E9: Japan | F9: 2
A10: Netherlands | B10: =COUNTIFS(jobs[job_location],$A10,jobs[work_year],year) -> 1 | E10: Slovenia | F10: 2
A11: Canada | B11: =COUNTIFS(jobs[job_location],$A11,jobs[work_year],year) -> 4 | E11: Nigeria | F11: 2
A12: Ukraine | B12: =COUNTIFS(jobs[job_location],$A12,jobs[work_year],year) -> 0 | E12: Singapore | F12: 2
A13: Italy | B13: =COUNTIFS(jobs[job_location],$A13,jobs[work_year],year) -> 0 | E13: Portugal | F13: 1
A14: Vietnam | B14: =COUNTIFS(jobs[job_location],$A14,jobs[work_year],year) -> 0 | E14: Netherlands | F14: 1
... A56: Iraq | B56: =COUNTIFS(jobs[job_location],$A56,jobs[work_year],year) -> 1 | E56: Israel | F56: 0

Sheet Dashboard
D1: Tech Job Salary Calculator
F5: Data Architect | J5: 2021
